Workbook

Sheet Summary
A1: TypeSafe / Jev: outside-in unit economics
A2: Built from public information only (as of Sep 29, 2026). Every estimate is labeled on the Assumptions tab. Not TypeSafe data.
A4: Key output (current selections) | B4: Value | C4: Where it comes from
A5: Serving setup | B5: =UnitEcon!$B$6 -> H100 SXM, BF16, 8B params | C5: Assumptions dropdowns
A6: List price ($ / M input tokens) | B6: =Assumptions!$B$6 -> 0.042 | C6: Confirmed, launch blog
A7: Est. cost to serve ($ / M tokens) | B7: =UnitEcon!$B$12 -> 0.056173464 | C7: UnitEcon
A8: Est. gross margin, BF16 | B8: =UnitEcon!$B$19 -> -0.39029462 | C8: UnitEcon
A9: Est. gross margin, FP8 | B9: =UnitEcon!$B$20 -> 0.30520395 | C9: UnitEcon
A10: Largest model that breaks even (B params, selected precision) | B10: =UnitEcon!$B$23 -> 5.7541761 | C10: UnitEcon
A11: Tokens per decision: Doom demo vs. sample finance workloads | B11: =TEXT(UnitEcon!$B$26,"#,##0")&" vs. "&TEXT(UnitEcon!$B$27,"#,##0") -> 4,630 vs. 453 | C11: UnitEcon / LiveTest
A12: Jev price per decision ($) | B12: =UnitEcon!$B$29 -> 3.8353e-05 | C12: UnitEcon
A13: Customer savings vs. fast LLM | B13: =UnitEcon!$B$36 -> 67.899947 | C13: UnitEcon
A14: Customer savings vs. reasoning LLM | B14: =UnitEcon!$B$39 -> 76.925751 | C14: UnitEcon
A15: Utilization needed for reserved GPUs to beat on-demand | B15: =UnitEcon!$B$41 -> 0.83333333 | C15: UnitEcon
A16: Runway, months: low / base / high cash | B16: =Runway!B33&" / "&Runway!B34&" / "&Runway!B35 -> 13 / 22 / 24 | C16: Runway (24 = at least 24)
A17: Hiring plan affordable? | B17: =Hiring!B13 -> YES: runway stays at or above target | C17: Hiring
A18: MEASURED: Jev billed input tokens per decision | B18: =LiveTest!B32 -> 913.16667 | C18: LiveTest (6 workloads)
A19: MEASURED: fixed tokens per call + multiplier on content | B19: =TEXT(LiveTest!B34,"#,##0")&" + "&TEXT(LiveTest!B35,"0.0")&"x" -> 179 + 1.6x | C19: LiveTest (6-point fit, rough)
A20: MEASURED: LLM cost / Jev cost, fast / reasoning | B20: =TEXT(LiveTest!C43,"0")&"x / "&TEXT(LiveTest!D43,"0")&"x" -> 69x / 65x | C20: LiveTest
A21: MEASURED: latency ms, Jev vs. fast / reasoning LLM | B21: =TEXT(LiveTest!B36,"#,##0")&" vs. "&TEXT(LiveTest!C41,"#,##0")&" / "&TEXT(LiveTest!D41,"#,##0") -> 261 vs. 4,588 / 2,984 | C21: LiveTest
A22: MEASURED: decision agreement, fast / reasoning | B22: =TEXT(LiveTest!C44,"0%")&" / "&TEXT(LiveTest!D44,"0%") -> 92% / 92% | C22: LiveTest (choice and yes/no only)
A25: Tabs
A26: Assumptions: every input with confidence and reasoning. Dropdowns switch GPU, precision, workload and comparison LLM.
A27: Hiring: current roster and a hiring plan with start months; checks runway against an 18-month target.
A28: UnitEcon: cost per token and per decision, BF16 vs FP8 margin, break-even model size, LLM comparison.
A29: Sensitivity: margin across model sizes, utilization, GPU types and GPU prices.
A30: Scale: the Jevons test, volume needed to cover fixed costs at different prices.
A31: Runway: 24-month monthly cash build, three cash cases, and the runway cost of the hiring plan.
A32: LiveTest: sample workload token counts, plus a paste area for your live API test results.
A33: Prices: GPU and LLM price and spec tables behind the dropdowns.
A34: Sources: where each public data point came from.
A36: Color key: blue = input, black = formula, green = link to another tab, yellow fill = dropdown or assumption that moves the answer most, grey fill = input area.

Sheet Assumptions
A1: Assumptions register
A2: Blue = input. Dropdowns in blue with yellow fill drive the lookups below them. Black = looked up or derived. Confidence: Confirmed / Reported / Estimate.
A4: Assumption | B4: Value | C4: Unit | D4: Confidence | E4: Reasoning / source
A5: A. Pricing and published data points
A6: Jev list price, input tokens | B6: 0.042 | C6: $ / M tokens | D6: Confirmed | E6: TypeSafe launch blog, Sep 15 2026 ($42 per billion tokens). Some third-party sites list $0.25-$0.42; the official figure is $0.042.
A7: Jev list price, output tokens | B7: 0 | C7: $ / M tokens | D7: Confirmed | E7: TypeSafe launch blog: output is free. Revenue depends entirely on input volume.
A8: Doom demo: cost per hour | B8: 7 | C8: $ / hour | D8: Confirmed (approx.) | E8: Launch blog says ~$7/hour; rounding means the implied tokens per call is +/- 15%.
A9: Doom demo: queries per second | B9: 10 | C9: queries / sec | D9: Confirmed | E9: Launch blog.
A10: Free signup credit | B10: 5 | C10: $ | D10: Reported | E10: Firecrawl write-up: signups opened Sep 20 with $5 credit. Verify when you sign up.
A11: B. Serving compute (none of this is disclosed by TypeSafe)
A12: Serving GPU | B12: H100 SXM | C12: dropdown | D12: Estimate | E12: =INDEX(Prices!$I$6:$I$9,MATCH($B$12,Prices!$A$6:$A$9,0)) -> The price-performance workhorse: mature software, abundant supply, falling rates. Committed estimate sits below the $3.84 market average; neocloud on-demand clusters around $2.70-$3.20.
A13: Serving precision | B13: BF16 | C13: dropdown | D13: Estimate | E13: BF16 is the conservative default. Many inference teams serve in FP8, which doubles throughput per GPU. TypeSafe hasn't said which it uses, and this one switch moves gross margin more than any other input.
A14: GPU cost, committed | B14: =INDEX(Prices!$B$6:$B$9,MATCH($B$12,Prices!$A$6:$A$9,0)) -> 2.5 | C14: $ / GPU-hour | D14: Estimate | E14: ="Committed rate for "&$B$12&". For reference: cheapest on-demand listing $"&TEXT(INDEX(Prices!$E$6:$E$9,MATCH($B$12,Prices!$A$6:$A$9,0)),"0.00")&"/hr (single GPUs, not reliable at scale). Edit the Prices tab to change." -> Committed rate for H100 SXM. For reference: cheapest on-demand listing $1.79/hr (single GPUs, not reliable at scale). Edit the Prices tab to change.
A15: GPU cost, on-demand (same provider tier) | B15: =INDEX(Prices!$C$6:$C$9,MATCH($B$12,Prices!$A$6:$A$9,0)) -> 3 | C15: $ / GPU-hour | D15: Estimate | E15: ="Same-tier on-demand for "&$B$12&", so the reserve-vs-rent test compares like with like (market average across all providers incl. hyperscalers: "&INDEX(Prices!$D$6:$D$9,MATCH($B$12,Prices!$A$6:$A$9,0))&")." -> Same-tier on-demand for H100 SXM, so the reserve-vs-rent test compares like with like (market average across all providers incl. hyperscalers: 3.84).
A16: GPU peak dense throughput | B16: =IF($B$13="FP8",INDEX(Prices!$G$6:$G$9,MATCH($B$12,Prices!$A$6:$A$9,0)),INDEX(Prices!$F$6:$F$9,MATCH($B$12,Prices!$A$6:$A$9,0))) -> 989 | C16: TFLOPS | D16: Spec | E16: =$B$12&" "&$B$13&" dense spec. Datasheets often quote sparse figures, which are 2x higher and not achievable for this workload." -> H100 SXM BF16 dense spec. Datasheets often quote sparse figures, which are 2x higher and not achievable for this workload.
A17: Model FLOPs utilization while serving | B17: 0.4 | C17: % | D17: Estimate | E17: Jev reads input and answers in one pass (no generation loop), the most GPU-efficient kind of work. 40-55% is realistic; 40% is the conservative end.
A18: Fleet utilization (paid GPU-hours doing billable work) | B18: 0.6 | C18: % | D18: Estimate | E18: Traffic is bursty and a 70-500 ms latency promise requires spare capacity for peaks. The lever TypeSafe controls most directly.
A19: Model size | B19: 8 | C19: B parameters | D19: Estimate - UNKNOWN | E19: Not disclosed; cannot be bounded from latency because a model can be split across GPUs (an 8B model reads 4,600 tokens in ~0.19s on one H100, ~25ms across eight). Use the break-even size on UnitEcon instead of defending this number.
A20: Serving overhead multiplier | B20: 1.2 | C20: x | D20: Estimate | E20: Checked: attention adds ~8% for an 8B model at this context length; batching gaps and networking add the rest.
A21: Share of billed tokens that is real compute | B21: 1 | C21: % | D21: Estimate - UNKNOWN | E21: Live test: Jev billed ~2x the request size (a fixed ~180 tokens per call plus ~1.6x the content; LiveTest rows 34-35). If part of that is a billing floor rather than GPU work, TypeSafe's cost per billed token is lower than the physics implies. 100% = every billed token is real work; try 50-70% to see the margin impact.
A22: C. Workload
A23: Tokens per decision: which source | B23: Live test | C23: dropdown | D23: Choice | E23: Doom demo = implied by TypeSafe's own billing ($7/hr at 10 qps), but game state is unusually large. Sample workloads = six finance/ops decisions counted offline (LiveTest tab). Live test = your measured API results once pasted into LiveTest.
A24: Input tokens per decision (used) | B24: =IF($B$23="Doom demo",$B$8/($B$9*3600)/($B$6/1000000),IF($B$23="Live test",IF(LiveTest!$B$32>0,LiveTest!$B$32,LiveTest!$E$13),LiveTest!$E$13)) -> 913.16667 | C24: tokens | D24: Derived | E24: ="Using: "&$B$23&IF(AND($B$23="Live test",LiveTest!$B$32=0)," (no live results pasted yet, falling back to sample workloads)","") -> Using: Live test
A25: Comparable LLM, case 1 (fast, no reasoning) | B25: Claude Haiku 4.5 | C25: dropdown | D25: Choice | E25: =INDEX(Prices!$G$14:$G$21,MATCH($B$25,Prices!$A$14:$A$21,0)) -> Fast, low-cost tier. MEASURED 371 visible output tokens: in the live test it ignored the JSON-only instruction and explained its answers. Prompt-dependent; a stricter prompt would likely cut this and its cost by 2-3x.
A26: Comparable LLM, case 2 (reasoning model) | B26: GPT-5.6 Terra | C26: dropdown | D26: Choice | E26: =INDEX(Prices!$G$14:$G$21,MATCH($B$26,Prices!$A$14:$A$21,0)) -> Closest to Jev in intelligence per TypeSafe. MEASURED 43 visible + 78 reasoning tokens on six simple decisions (pre-test guess was 1,000 reasoning). Harder multi-step workflows would use more.
A27: LLM input tokens vs. Jev billed tokens, same decision | B27: =IF(COUNT(LiveTest!$H$18:$H$29)=0,150,ROUND(AVERAGE(LiveTest!$H$18:$H$29)-AVERAGE(LiveTest!$C$18:$C$29),0)) -> -164 | C27: tokens | D27: Measured | E27: From the live test: LLMs were sent fewer input tokens than Jev billed for the same decision, even with extra formatting instructions, so this is negative. Falls back to +150 (the pre-test guess) if no live results are pasted.
A28: D. Company and cash
A29: Seed raised | B29: 40 | C29: $mm | D29: Confirmed | E29: Seed led by DCVC, announced Sep 15 2026.
A30: Seed valuation | B30: 200 | C30: $mm | D30: Reported | E30: Forbes, citing a person familiar; not confirmed by TypeSafe.
A31: Cash on hand today: low case | B31: 20 | C31: $mm | D31: Estimate - UNKNOWN | E31: Two years of stealth spending may have used much of the seed.
A32: Cash on hand today: base case | B32: 30 | C32: $mm | D32: Estimate - UNKNOWN
A33: Cash on hand today: high case | B33: 40 | C33: $mm | D33: Estimate - UNKNOWN | E33: If the seed closed recently (announcements often lag closings) and earlier costs were covered by other money or credits.
A34: Current headcount | B34: =Hiring!$D$32 -> 25 | C34: people | D34: From Hiring tab | E34: Roster on the Hiring tab (25, matching the reported headcount).
A35: Current payroll, fully loaded | B35: =Hiring!$H$32/1000 -> 8.1825 | C35: $mm / year | D35: From Hiring tab | E35: Cash cost only. Equity is a large part of AI-lab pay but doesn't burn cash.
A36: Minimum runway target | B36: 18 | C36: months | D36: Policy choice | E36: Common startup rule: keep at least 18 months so you can raise from strength. Drives the hire check on the Hiring tab.
A37: Other opex (rent, software, legal, insurance) | B37: 3 | C37: $mm / year | D37: Estimate | E37: SF office near Embarcadero for 25-50 people plus the usual overhead.
A38: Research GPU | B38: H100 SXM | C38: dropdown | D38: Estimate | E38: =INDEX(Prices!$I$6:$I$9,MATCH($B$38,Prices!$A$6:$A$9,0)) -> The price-performance workhorse: mature software, abundant supply, falling rates. Committed estimate sits below the $3.84 market average; neocloud on-demand clusters around $2.70-$3.20.
A39: Research / training GPUs | B39: 256 | C39: GPUs | D39: Estimate | E39: Cut from 512: at 512 GPUs plus payroll, two years of stealth would have cost more than the $40M seed. Either they used less compute, had cloud credits, or raised undisclosed earlier money. Worth asking.
A40: Research GPU rate | B40: =INDEX(Prices!$B$6:$B$9,MATCH($B$38,Prices!$A$6:$A$9,0)) -> 2.5 | C40: $ / GPU-hour | D40: Estimate | E40: ="Committed rate for "&$B$38&" from the Prices tab." -> Committed rate for H100 SXM from the Prices tab.
A41: E. Revenue leakage and free credits
...

Sheet Hiring
A1: Hiring plan and affordability check
A2: Current roster is fixed. Add planned hires below with a start month; payroll and runway update everywhere.
A4: Hire check
A5: Current headcount | B5: =D32 -> 25
A6: Current annual payroll, fully loaded ($mm) | B6: =H32/1000 -> 8.1825
A7: Planned hires (people) | B7: =SUM(D37:D66) -> 1
A8: Headcount at month 24 | B8: =Runway!Y5 -> 26
A9: Payroll at month 24, annualized ($mm) | B9: =Runway!Y6*12 -> 8.42
A10: Minimum runway target (months) | B10: =Assumptions!$B$36 -> 18
A11: Runway on base-case cash with this plan (months; 24 = at least 24) | B11: =Runway!B34 -> 22
A12: Runway used up by the planned hires (months) | B12: =Runway!B37 -> 1
A13: Can we afford this plan? | B13: =IF(B11>=B10,"YES: runway stays at or above target","NO: runway falls below target. Delay start months or cut hires.") -> YES: runway stays at or above target
A15: Current team (fixed)
A16: Role | B16: Function | C16: Type | D16: Count | E16: Base salary ($k, est.) | F16: Load factor | G16: Loaded cost / person ($k) | H16: Annual cost ($k) | J16: Notes
A17: Co-founder | B17: Leadership | C17: FTE | D17: 3 | E17: 250 | F17: =IF(C17="Contract",1,IF(C17="FTE",$B$70,0)) -> 1.25 | G17: =E17*F17 -> 312.5 | H17: =D17*G17 -> 937.5 | J17: Fixed. Founders often take below-market cash.
A18: Member of Technical Staff | B18: R&D | C18: FTE | D18: 13 | E18: 300 | F18: =IF(C18="Contract",1,IF(C18="FTE",$B$70,0)) -> 1.25 | G18: =E18*F18 -> 375 | H18: =D18*G18 -> 4875 | J18: Core research and engineering; ex-OpenAI / Google Brain / FAIR talent.
A19: Research Engineer | B19: R&D | C19: FTE | D19: 1 | E19: 280 | F19: =IF(C19="Contract",1,IF(C19="FTE",$B$70,0)) -> 1.25 | G19: =E19*F19 -> 350 | H19: =D19*G19 -> 350
A20: Developer Platform | B20: R&D | C20: FTE | D20: 1 | E20: 260 | F20: =IF(C20="Contract",1,IF(C20="FTE",$B$70,0)) -> 1.25 | G20: =E20*F20 -> 325 | H20: =D20*G20 -> 325 | J20: API, SDKs, console.
A21: Product | B21: Product | C21: FTE | D21: 2 | E21: 230 | F21: =IF(C21="Contract",1,IF(C21="FTE",$B$70,0)) -> 1.25 | G21: =E21*F21 -> 287.5 | H21: =D21*G21 -> 575 | J21: Listed twice in the roster, so counted as 2.
A22: GTM | B22: GTM | C22: FTE | D22: 1 | E22: 200 | F22: =IF(C22="Contract",1,IF(C22="FTE",$B$70,0)) -> 1.25 | G22: =E22*F22 -> 250 | H22: =D22*G22 -> 250
A23: Developer Advocate | B23: GTM | C23: FTE | D23: 1 | E23: 190 | F23: =IF(C23="Contract",1,IF(C23="FTE",$B$70,0)) -> 1.25 | G23: =E23*F23 -> 237.5 | H23: =D23*G23 -> 237.5
A24: Chief of Staff | B24: G&A | C24: FTE | D24: 1 | E24: 200 | F24: =IF(C24="Contract",1,IF(C24="FTE",$B$70,0)) -> 1.25 | G24: =E24*F24 -> 250 | H24: =D24*G24 -> 250
A25: Head of Recruiting | B25: G&A | C25: FTE | D25: 1 | E25: 210 | F25: =IF(C25="Contract",1,IF(C25="FTE",$B$70,0)) -> 1.25 | G25: =E25*F25 -> 262.5 | H25: =D25*G25 -> 262.5
A26: SEO consultant | B26: GTM | C26: Contract | D26: 1 | E26: 120 | F26: =IF(C26="Contract",1,IF(C26="FTE",$B$70,0)) -> 1 | G26: =E26*F26 -> 120 | H26: =D26*G26 -> 120 | J26: Contract: annual contract value, no benefits load.
F27: =IF(C27="Contract",1,IF(C27="FTE",$B$70,0)) -> 0 | G27: =E27*F27 -> 0 | H27: =D27*G27 -> 0
F28: =IF(C28="Contract",1,IF(C28="FTE",$B$70,0)) -> 0 | G28: =E28*F28 -> 0 | H28: =D28*G28 -> 0
F29: =IF(C29="Contract",1,IF(C29="FTE",$B$70,0)) -> 0 | G29: =E29*F29 -> 0 | H29: =D29*G29 -> 0
F30: =IF(C30="Contract",1,IF(C30="FTE",$B$70,0)) -> 0 | G30: =E30*F30 -> 0 | H30: =D30*G30 -> 0
F31: =IF(C31="Contract",1,IF(C31="FTE",$B$70,0)) -> 0 | G31: =E31*F31 -> 0 | H31: =D31*G31 -> 0
A32: Total current team | D32: =SUM(D17:D31) -> 25 | H32: =SUM(H17:H31) -> 8182.5
A35: Planned hires: add a row per role, set the start month (1-24)
A36: Role | B36: Function | C36: Type | D36: Count | E36: Start month | F36: Base salary ($k, est.) | G36: Load factor | H36: Loaded cost / person ($k) | I36: Annual run-rate ($k) | J36: Notes
A37: Finance & Business Planning | B37: G&A | C37: FTE | D37: 1 | E37: 2 | F37: 190 | G37: =IF(C37="Contract",1,IF(C37="FTE",$B$70,0)) -> 1.25 | H37: =F37*G37 -> 237.5 | I37: =D37*H37 -> 237.5 | J37: Example row: the role you're applying for.
G38: =IF(C38="Contract",1,IF(C38="FTE",$B$70,0)) -> 0 | H38: =F38*G38 -> 0 | I38: =D38*H38 -> 0
G39: =IF(C39="Contract",1,IF(C39="FTE",$B$70,0)) -> 0 | H39: =F39*G39 -> 0 | I39: =D39*H39 -> 0
G40: =IF(C40="Contract",1,IF(C40="FTE",$B$70,0)) -> 0 | H40: =F40*G40 -> 0 | I40: =D40*H40 -> 0
G41: =IF(C41="Contract",1,IF(C41="FTE",$B$70,0)) -> 0 | H41: =F41*G41 -> 0 | I41: =D41*H41 -> 0
G42: =IF(C42="Contract",1,IF(C42="FTE",$B$70,0)) -> 0 | H42: =F42*G42 -> 0 | I42: =D42*H42 -> 0
G43: =IF(C43="Contract",1,IF(C43="FTE",$B$70,0)) -> 0 | H43: =F43*G43 -> 0 | I43: =D43*H43 -> 0
G44: =IF(C44="Contract",1,IF(C44="FTE",$B$70,0)) -> 0 | H44: =F44*G44 -> 0 | I44: =D44*H44 -> 0
...

Sheet UnitEcon
A1: Unit economics: what one token and one decision cost vs. earn
A2: All cells are formulas off Assumptions and Prices. Change the dropdowns on Assumptions to switch GPU, precision, workload and LLM.
A4: Line item | B4: Value | C4: Unit | D4: How it's calculated
A5: 1. Cost to serve
A6: Serving setup selected | B6: =Assumptions!$B$12&", "&Assumptions!$B$13&", "&TEXT(Assumptions!$B$19,"0")&"B params" -> H100 SXM, BF16, 8B params | D6: From Assumptions dropdowns
A7: FLOPs per input token | B7: =2*Assumptions!$B$19*1000000000 -> 16000000000 | C7: FLOPs | D7: 2 x parameters (one forward pass, no generation loop)
A8: Effective FLOP/s per GPU | B8: =Assumptions!$B$16*1000000000000*Assumptions!$B$17 -> 395600000000000 | C8: FLOP / s | D8: Dense peak x MFU
A9: Tokens per second per GPU (when busy) | B9: =B8/B7/Assumptions!$B$20 -> 20604.167 | C9: tokens / s | D9: Effective FLOP/s / FLOPs per token / overhead
A10: Tokens per GPU-hour (when busy) | B10: =B9*3600 -> 74175000 | C10: tokens
A11: Cost per M tokens at 100% utilization | B11: =Assumptions!$B$14/(B10/1000000)*Assumptions!$B$21 -> 0.033704078 | C11: $ / M tokens | D11: GPU rate / M tokens per hour x share of billed tokens that is real compute
A12: Cost per M tokens at fleet utilization | B12: =B11/Assumptions!$B$18 -> 0.056173464 | C12: $ / M tokens | D12: Idle hours still get paid for
A13: 2. Price vs. cost
A14: List price | B14: =Assumptions!$B$6 -> 0.042 | C14: $ / M tokens | D14: Linked
A15: Revenue leakage (gateway + payment fees) | B15: =Assumptions!$B$42*Assumptions!$B$43+(1-Assumptions!$B$42)*Assumptions!$B$44 -> 0.038 | C15: % | D15: Gateway share x fee + direct share x processing fee
A16: Net price received | B16: =B14*(1-B15) -> 0.040404 | C16: $ / M tokens | D16: What TypeSafe keeps
A17: Gross profit per M tokens | B17: =B16-B12 -> -0.015769464 | C17: $ / M tokens | D17: Net price - cost
A18: Gross margin (selected precision) | B18: =IF(B16=0,0,B17/B16) -> -0.39029462 | C18: %
A19: Gross margin if served in BF16 | B19: =IF(B16=0,0,1-(Assumptions!$B$14*2*Assumptions!$B$19*1000000000*Assumptions!$B$20/(INDEX(Prices!$F$6:$F$9,MATCH(Assumptions!$B$12,Prices!$A$6:$A$9,0))*1000000000000*Assumptions!$B$17*3600*Assumptions!$B$18)*1000000)*Assumptions!$B$21/B16) -> -0.39029462 | C19: % | D19: Same setup, BF16 throughput
A20: Gross margin if served in FP8 | B20: =IF(B16=0,0,1-(Assumptions!$B$14*2*Assumptions!$B$19*1000000000*Assumptions!$B$20/(INDEX(Prices!$G$6:$G$9,MATCH(Assumptions!$B$12,Prices!$A$6:$A$9,0))*1000000000000*Assumptions!$B$17*3600*Assumptions!$B$18)*1000000)*Assumptions!$B$21/B16) -> 0.30520395 | C20: % | D20: Same setup, FP8 throughput
A21: Net revenue per GPU-hour, fully busy | B21: =B10/1000000*B16 -> 2.9969667 | C21: $ / GPU-hour | D21: Ceiling on what one GPU can earn
A22: Net revenue per paid GPU-hour at fleet utilization | B22: =B21*Assumptions!$B$18 -> 1.79818 | C22: $ / GPU-hour | D22: Compare with the GPU rate
A23: Break-even model size at this utilization | B23: =B16/1000000*Assumptions!$B$16*1000000000000*Assumptions!$B$17*3600*Assumptions!$B$18/(Assumptions!$B$14*2*Assumptions!$B$20*Assumptions!$B$21)/1000000000 -> 5.7541761 | C23: B parameters | D23: Largest model that still covers compute at list price
A24: Break-even utilization at this model size | B24: =IF(B16=0,0,B11/B16) -> 0.83417677 | C24: % | D24: Above 100% = can't break even at any utilization
A25: 3. Per decision
A26: Tokens per decision implied by Doom demo | B26: =Assumptions!$B$8/(Assumptions!$B$9*3600)/(Assumptions!$B$6/1000000) -> 4629.6296 | C26: tokens | D26: $7/hr / 36,000 queries / price per token
A27: Tokens per decision, sample finance workloads | B27: =LiveTest!$E$13 -> 452.5 | C27: tokens | D27: Average of six workloads counted offline (LiveTest)
A28: Tokens per decision used | B28: =Assumptions!$B$24 -> 913.16667 | C28: tokens | D28: ="Source: "&Assumptions!$B$23 -> Source: Live test
A29: Jev list price per decision | B29: =B28/1000000*B14 -> 3.8353e-05 | C29: $
A30: Jev cost to serve per decision | B30: =B28/1000000*B12 -> 5.1295735e-05 | C30: $
A31: Decisions per $1 of list revenue | B31: =IF(B29=0,0,1/B29) -> 26073.58 | C31: decisions
A32: Decisions covered by free signup credit | B32: =IF(B29=0,0,Assumptions!$B$10/B29) -> 130367.9 | C32: decisions
A33: 4. Customer savings vs. LLMs
A34: Case 1 model (fast) | B34: =Assumptions!$B$25 -> Claude Haiku 4.5 | D34: Assumptions dropdown
A35: Case 1 price per decision | B35: =(B28+Assumptions!$B$27)/1000000*INDEX(Prices!$B$14:$B$21,MATCH(Assumptions!$B$25,Prices!$A$14:$A$21,0))+(INDEX(Prices!$E$14:$E$21,MATCH(Assumptions!$B$25,Prices!$A$14:$A$21,0))+INDEX(Prices!$F$14:$F$21,MATCH(Assumptions!$B$25,Prices!$A$14:$A$21,0)))/1000000*INDEX(Prices!$C$14:$C$21,MATCH(Assumptions!$B$25,Prices!$A$14:$A$21,0)) -> 0.0026041667 | C35: $ | D35: Input incl. format instructions + output + reasoning tokens
A36: Case 1: LLM price / Jev price | B36: =IF(B29=0,0,B35/B29) -> 67.899947 | C36: x | D36: Customer's savings multiple
A37: Case 2 model (reasoning) | B37: =Assumptions!$B$26 -> GPT-5.6 Terra | D37: Assumptions dropdown
A38: Case 2 price per decision | B38: =(B28+Assumptions!$B$27)/1000000*INDEX(Prices!$B$14:$B$21,MATCH(Assumptions!$B$26,Prices!$A$14:$A$21,0))+(INDEX(Prices!$E$14:$E$21,MATCH(Assumptions!$B$26,Prices!$A$14:$A$21,0))+INDEX(Prices!$F$14:$F$21,MATCH(Assumptions!$B$26,Prices!$A$14:$A$21,0)))/1000000*INDEX(Prices!$C$14:$C$21,MATCH(Assumptions!$B$26,Prices!$A$14:$A$21,0)) -> 0.0029503333 | C38: $ | D38: Reasoning tokens usually dominate the bill
A39: Case 2: LLM price / Jev price | B39: =IF(B29=0,0,B38/B29) -> 76.925751 | C39: x | D39: Compare with TypeSafe's claimed 444x on its workflow evals
A40: 5. Capacity commitment test
A41: Utilization needed for reserved capacity to beat on-demand | B41: =Assumptions!$B$14/Assumptions!$B$15 -> 0.83333333 | C41: % | D41: Reserve only if reserved GPUs will be busier than this; same provider tier

Sheet Sensitivity
A1: Sensitivity: when does the price cover compute?
A2: Grids follow the GPU, precision and other inputs selected on Assumptions. Red = selling below cost.
A4: Table 1. Gross margin by model size (rows, B params) and fleet utilization (columns)
A5: Params (B) \ Util | B5: 0.3 | C5: 0.45 | D5: 0.6 | E5: 0.75 | F5: 0.9
A6: 1 | B6: =IF(UnitEcon!$B$16=0,0,1-(Assumptions!$B$14*2*$A6*1000000000*Assumptions!$B$20/(Assumptions!$B$16*1000000000000*Assumptions!$B$17*3600*B$5)*1000000*Assumptions!$B$21)/UnitEcon!$B$16) -> 0.65242635 | C6: =IF(UnitEcon!$B$16=0,0,1-(Assumptions!$B$14*2*$A6*1000000000*Assumptions!$B$20/(Assumptions!$B$16*1000000000000*Assumptions!$B$17*3600*C$5)*1000000*Assumptions!$B$21)/UnitEcon!$B$16) -> 0.76828423 | D6: =IF(UnitEcon!$B$16=0,0,1-(Assumptions!$B$14*2*$A6*1000000000*Assumptions!$B$20/(Assumptions!$B$16*1000000000000*Assumptions!$B$17*3600*D$5)*1000000*Assumptions!$B$21)/UnitEcon!$B$16) -> 0.82621317 | E6: =IF(UnitEcon!$B$16=0,0,1-(Assumptions!$B$14*2*$A6*1000000000*Assumptions!$B$20/(Assumptions!$B$16*1000000000000*Assumptions!$B$17*3600*E$5)*1000000*Assumptions!$B$21)/UnitEcon!$B$16) -> 0.86097054 | F6: =IF(UnitEcon!$B$16=0,0,1-(Assumptions!$B$14*2*$A6*1000000000*Assumptions!$B$20/(Assumptions!$B$16*1000000000000*Assumptions!$B$17*3600*F$5)*1000000*Assumptions!$B$21)/UnitEcon!$B$16) -> 0.88414212
A7: 3 | B7: =IF(UnitEcon!$B$16=0,0,1-(Assumptions!$B$14*2*$A7*1000000000*Assumptions!$B$20/(Assumptions!$B$16*1000000000000*Assumptions!$B$17*3600*B$5)*1000000*Assumptions!$B$21)/UnitEcon!$B$16) -> -0.042720962 | C7: =IF(UnitEcon!$B$16=0,0,1-(Assumptions!$B$14*2*$A7*1000000000*Assumptions!$B$20/(Assumptions!$B$16*1000000000000*Assumptions!$B$17*3600*C$5)*1000000*Assumptions!$B$21)/UnitEcon!$B$16) -> 0.30485269 | D7: =IF(UnitEcon!$B$16=0,0,1-(Assumptions!$B$14*2*$A7*1000000000*Assumptions!$B$20/(Assumptions!$B$16*1000000000000*Assumptions!$B$17*3600*D$5)*1000000*Assumptions!$B$21)/UnitEcon!$B$16) -> 0.47863952 | E7: =IF(UnitEcon!$B$16=0,0,1-(Assumptions!$B$14*2*$A7*1000000000*Assumptions!$B$20/(Assumptions!$B$16*1000000000000*Assumptions!$B$17*3600*E$5)*1000000*Assumptions!$B$21)/UnitEcon!$B$16) -> 0.58291162 | F7: =IF(UnitEcon!$B$16=0,0,1-(Assumptions!$B$14*2*$A7*1000000000*Assumptions!$B$20/(Assumptions!$B$16*1000000000000*Assumptions!$B$17*3600*F$5)*1000000*Assumptions!$B$21)/UnitEcon!$B$16) -> 0.65242635
A8: 8 | B8: =IF(UnitEcon!$B$16=0,0,1-(Assumptions!$B$14*2*$A8*1000000000*Assumptions!$B$20/(Assumptions!$B$16*1000000000000*Assumptions!$B$17*3600*B$5)*1000000*Assumptions!$B$21)/UnitEcon!$B$16) -> -1.7805892 | C8: =IF(UnitEcon!$B$16=0,0,1-(Assumptions!$B$14*2*$A8*1000000000*Assumptions!$B$20/(Assumptions!$B$16*1000000000000*Assumptions!$B$17*3600*C$5)*1000000*Assumptions!$B$21)/UnitEcon!$B$16) -> -0.85372615 | D8: =IF(UnitEcon!$B$16=0,0,1-(Assumptions!$B$14*2*$A8*1000000000*Assumptions!$B$20/(Assumptions!$B$16*1000000000000*Assumptions!$B$17*3600*D$5)*1000000*Assumptions!$B$21)/UnitEcon!$B$16) -> -0.39029462 | E8: =IF(UnitEcon!$B$16=0,0,1-(Assumptions!$B$14*2*$A8*1000000000*Assumptions!$B$20/(Assumptions!$B$16*1000000000000*Assumptions!$B$17*3600*E$5)*1000000*Assumptions!$B$21)/UnitEcon!$B$16) -> -0.11223569 | F8: =IF(UnitEcon!$B$16=0,0,1-(Assumptions!$B$14*2*$A8*1000000000*Assumptions!$B$20/(Assumptions!$B$16*1000000000000*Assumptions!$B$17*3600*F$5)*1000000*Assumptions!$B$21)/UnitEcon!$B$16) -> 0.073136923
A9: 14 | B9: =IF(UnitEcon!$B$16=0,0,1-(Assumptions!$B$14*2*$A9*1000000000*Assumptions!$B$20/(Assumptions!$B$16*1000000000000*Assumptions!$B$17*3600*B$5)*1000000*Assumptions!$B$21)/UnitEcon!$B$16) -> -3.8660312 | C9: =IF(UnitEcon!$B$16=0,0,1-(Assumptions!$B$14*2*$A9*1000000000*Assumptions!$B$20/(Assumptions!$B$16*1000000000000*Assumptions!$B$17*3600*C$5)*1000000*Assumptions!$B$21)/UnitEcon!$B$16) -> -2.2440208 | D9: =IF(UnitEcon!$B$16=0,0,1-(Assumptions!$B$14*2*$A9*1000000000*Assumptions!$B$20/(Assumptions!$B$16*1000000000000*Assumptions!$B$17*3600*D$5)*1000000*Assumptions!$B$21)/UnitEcon!$B$16) -> -1.4330156 | E9: =IF(UnitEcon!$B$16=0,0,1-(Assumptions!$B$14*2*$A9*1000000000*Assumptions!$B$20/(Assumptions!$B$16*1000000000000*Assumptions!$B$17*3600*E$5)*1000000*Assumptions!$B$21)/UnitEcon!$B$16) -> -0.94641246 | F9: =IF(UnitEcon!$B$16=0,0,1-(Assumptions!$B$14*2*$A9*1000000000*Assumptions!$B$20/(Assumptions!$B$16*1000000000000*Assumptions!$B$17*3600*F$5)*1000000*Assumptions!$B$21)/UnitEcon!$B$16) -> -0.62201039
A10: 30 | B10: =IF(UnitEcon!$B$16=0,0,1-(Assumptions!$B$14*2*$A10*1000000000*Assumptions!$B$20/(Assumptions!$B$16*1000000000000*Assumptions!$B$17*3600*B$5)*1000000*Assumptions!$B$21)/UnitEcon!$B$16) -> -9.4272096 | C10: =IF(UnitEcon!$B$16=0,0,1-(Assumptions!$B$14*2*$A10*1000000000*Assumptions!$B$20/(Assumptions!$B$16*1000000000000*Assumptions!$B$17*3600*C$5)*1000000*Assumptions!$B$21)/UnitEcon!$B$16) -> -5.9514731 | D10: =IF(UnitEcon!$B$16=0,0,1-(Assumptions!$B$14*2*$A10*1000000000*Assumptions!$B$20/(Assumptions!$B$16*1000000000000*Assumptions!$B$17*3600*D$5)*1000000*Assumptions!$B$21)/UnitEcon!$B$16) -> -4.2136048 | E10: =IF(UnitEcon!$B$16=0,0,1-(Assumptions!$B$14*2*$A10*1000000000*Assumptions!$B$20/(Assumptions!$B$16*1000000000000*Assumptions!$B$17*3600*E$5)*1000000*Assumptions!$B$21)/UnitEcon!$B$16) -> -3.1708838 | F10: =IF(UnitEcon!$B$16=0,0,1-(Assumptions!$B$14*2*$A10*1000000000*Assumptions!$B$20/(Assumptions!$B$16*1000000000000*Assumptions!$B$17*3600*F$5)*1000000*Assumptions!$B$21)/UnitEcon!$B$16) -> -2.4757365
A11: 70 | B11: =IF(UnitEcon!$B$16=0,0,1-(Assumptions!$B$14*2*$A11*1000000000*Assumptions!$B$20/(Assumptions!$B$16*1000000000000*Assumptions!$B$17*3600*B$5)*1000000*Assumptions!$B$21)/UnitEcon!$B$16) -> -23.330156 | C11: =IF(UnitEcon!$B$16=0,0,1-(Assumptions!$B$14*2*$A11*1000000000*Assumptions!$B$20/(Assumptions!$B$16*1000000000000*Assumptions!$B$17*3600*C$5)*1000000*Assumptions!$B$21)/UnitEcon!$B$16) -> -15.220104 | D11: =IF(UnitEcon!$B$16=0,0,1-(Assumptions!$B$14*2*$A11*1000000000*Assumptions!$B$20/(Assumptions!$B$16*1000000000000*Assumptions!$B$17*3600*D$5)*1000000*Assumptions!$B$21)/UnitEcon!$B$16) -> -11.165078 | E11: =IF(UnitEcon!$B$16=0,0,1-(Assumptions!$B$14*2*$A11*1000000000*Assumptions!$B$20/(Assumptions!$B$16*1000000000000*Assumptions!$B$17*3600*E$5)*1000000*Assumptions!$B$21)/UnitEcon!$B$16) -> -8.7320623 | F11: =IF(UnitEcon!$B$16=0,0,1-(Assumptions!$B$14*2*$A11*1000000000*Assumptions!$B$20/(Assumptions!$B$16*1000000000000*Assumptions!$B$17*3600*F$5)*1000000*Assumptions!$B$21)/UnitEcon!$B$16) -> -7.1100519
A13: Table 2. Gross margin by GPU (rows) and precision (columns), at selected model size and utilization
A14: GPU \ Precision | B14: BF16 | C14: FP8
A15: H100 SXM | B15: =IF(UnitEcon!$B$16=0,0,1-(INDEX(Prices!$B$6:$B$9,MATCH($A15,Prices!$A$6:$A$9,0))*2*Assumptions!$B$19*1000000000*Assumptions!$B$20/(INDEX(Prices!$F$6:$F$9,MATCH($A15,Prices!$A$6:$A$9,0))*1000000000000*Assumptions!$B$17*3600*Assumptions!$B$18)*1000000*Assumptions!$B$21)/UnitEcon!$B$16) -> -0.39029462 | C15: =IF(UnitEcon!$B$16=0,0,1-(INDEX(Prices!$B$6:$B$9,MATCH($A15,Prices!$A$6:$A$9,0))*2*Assumptions!$B$19*1000000000*Assumptions!$B$20/(INDEX(Prices!$G$6:$G$9,MATCH($A15,Prices!$A$6:$A$9,0))*1000000000000*Assumptions!$B$17*3600*Assumptions!$B$18)*1000000*Assumptions!$B$21)/UnitEcon!$B$16) -> 0.30520395
A16: H200 | B16: =IF(UnitEcon!$B$16=0,0,1-(INDEX(Prices!$B$6:$B$9,MATCH($A16,Prices!$A$6:$A$9,0))*2*Assumptions!$B$19*1000000000*Assumptions!$B$20/(INDEX(Prices!$F$6:$F$9,MATCH($A16,Prices!$A$6:$A$9,0))*1000000000000*Assumptions!$B$17*3600*Assumptions!$B$18)*1000000*Assumptions!$B$21)/UnitEcon!$B$16) -> -0.61274175 | C16: =IF(UnitEcon!$B$16=0,0,1-(INDEX(Prices!$B$6:$B$9,MATCH($A16,Prices!$A$6:$A$9,0))*2*Assumptions!$B$19*1000000000*Assumptions!$B$20/(INDEX(Prices!$G$6:$G$9,MATCH($A16,Prices!$A$6:$A$9,0))*1000000000000*Assumptions!$B$17*3600*Assumptions!$B$18)*1000000*Assumptions!$B$21)/UnitEcon!$B$16) -> 0.19403659
A17: B200 | B17: =IF(UnitEcon!$B$16=0,0,1-(INDEX(Prices!$B$6:$B$9,MATCH($A17,Prices!$A$6:$A$9,0))*2*Assumptions!$B$19*1000000000*Assumptions!$B$20/(INDEX(Prices!$F$6:$F$9,MATCH($A17,Prices!$A$6:$A$9,0))*1000000000000*Assumptions!$B$17*3600*Assumptions!$B$18)*1000000*Assumptions!$B$21)/UnitEcon!$B$16) -> 0.022221244 | C17: =IF(UnitEcon!$B$16=0,0,1-(INDEX(Prices!$B$6:$B$9,MATCH($A17,Prices!$A$6:$A$9,0))*2*Assumptions!$B$19*1000000000*Assumptions!$B$20/(INDEX(Prices!$G$6:$G$9,MATCH($A17,Prices!$A$6:$A$9,0))*1000000000000*Assumptions!$B$17*3600*Assumptions!$B$18)*1000000*Assumptions!$B$21)/UnitEcon!$B$16) -> 0.51111062
A18: B300 | B18: =IF(UnitEcon!$B$16=0,0,1-(INDEX(Prices!$B$6:$B$9,MATCH($A18,Prices!$A$6:$A$9,0))*2*Assumptions!$B$19*1000000000*Assumptions!$B$20/(INDEX(Prices!$F$6:$F$9,MATCH($A18,Prices!$A$6:$A$9,0))*1000000000000*Assumptions!$B$17*3600*Assumptions!$B$18)*1000000*Assumptions!$B$21)/UnitEcon!$B$16) -> -0.17333451 | C18: =IF(UnitEcon!$B$16=0,0,1-(INDEX(Prices!$B$6:$B$9,MATCH($A18,Prices!$A$6:$A$9,0))*2*Assumptions!$B$19*1000000000*Assumptions!$B$20/(INDEX(Prices!$G$6:$G$9,MATCH($A18,Prices!$A$6:$A$9,0))*1000000000000*Assumptions!$B$17*3600*Assumptions!$B$18)*1000000*Assumptions!$B$21)/UnitEcon!$B$16) -> 0.41333275
A20: Table 3. Cost to serve ($ per M tokens) by GPU rate (rows) and model size (columns), selected GPU and precision
A21: GPU $/hr \ Params (B) | B21: 1 | C21: 3 | D21: 8 | E21: 14 | F21: 30 | G21: 70
A22: 1.79 | B22: =$A22*2*B$21*1000000000*Assumptions!$B$20/(Assumptions!$B$16*1000000000000*Assumptions!$B$17*3600*Assumptions!$B$18)*1000000*Assumptions!$B$21 -> 0.005027525 | C22: =$A22*2*C$21*1000000000*Assumptions!$B$20/(Assumptions!$B$16*1000000000000*Assumptions!$B$17*3600*Assumptions!$B$18)*1000000*Assumptions!$B$21 -> 0.015082575 | D22: =$A22*2*D$21*1000000000*Assumptions!$B$20/(Assumptions!$B$16*1000000000000*Assumptions!$B$17*3600*Assumptions!$B$18)*1000000*Assumptions!$B$21 -> 0.0402202 | E22: =$A22*2*E$21*1000000000*Assumptions!$B$20/(Assumptions!$B$16*1000000000000*Assumptions!$B$17*3600*Assumptions!$B$18)*1000000*Assumptions!$B$21 -> 0.07038535 | F22: =$A22*2*F$21*1000000000*Assumptions!$B$20/(Assumptions!$B$16*1000000000000*Assumptions!$B$17*3600*Assumptions!$B$18)*1000000*Assumptions!$B$21 -> 0.15082575 | G22: =$A22*2*G$21*1000000000*Assumptions!$B$20/(Assumptions!$B$16*1000000000000*Assumptions!$B$17*3600*Assumptions!$B$18)*1000000*Assumptions!$B$21 -> 0.35192675
A23: 2.25 | B23: =$A23*2*B$21*1000000000*Assumptions!$B$20/(Assumptions!$B$16*1000000000000*Assumptions!$B$17*3600*Assumptions!$B$18)*1000000*Assumptions!$B$21 -> 0.0063195147 | C23: =$A23*2*C$21*1000000000*Assumptions!$B$20/(Assumptions!$B$16*1000000000000*Assumptions!$B$17*3600*Assumptions!$B$18)*1000000*Assumptions!$B$21 -> 0.018958544 | D23: =$A23*2*D$21*1000000000*Assumptions!$B$20/(Assumptions!$B$16*1000000000000*Assumptions!$B$17*3600*Assumptions!$B$18)*1000000*Assumptions!$B$21 -> 0.050556117 | E23: =$A23*2*E$21*1000000000*Assumptions!$B$20/(Assumptions!$B$16*1000000000000*Assumptions!$B$17*3600*Assumptions!$B$18)*1000000*Assumptions!$B$21 -> 0.088473205 | F23: =$A23*2*F$21*1000000000*Assumptions!$B$20/(Assumptions!$B$16*1000000000000*Assumptions!$B$17*3600*Assumptions!$B$18)*1000000*Assumptions!$B$21 -> 0.18958544 | G23: =$A23*2*G$21*1000000000*Assumptions!$B$20/(Assumptions!$B$16*1000000000000*Assumptions!$B$17*3600*Assumptions!$B$18)*1000000*Assumptions!$B$21 -> 0.44236603
A24: 2.5 | B24: =$A24*2*B$21*1000000000*Assumptions!$B$20/(Assumptions!$B$16*1000000000000*Assumptions!$B$17*3600*Assumptions!$B$18)*1000000*Assumptions!$B$21 -> 0.007021683 | C24: =$A24*2*C$21*1000000000*Assumptions!$B$20/(Assumptions!$B$16*1000000000000*Assumptions!$B$17*3600*Assumptions!$B$18)*1000000*Assumptions!$B$21 -> 0.021065049 | D24: =$A24*2*D$21*1000000000*Assumptions!$B$20/(Assumptions!$B$16*1000000000000*Assumptions!$B$17*3600*Assumptions!$B$18)*1000000*Assumptions!$B$21 -> 0.056173464 | E24: =$A24*2*E$21*1000000000*Assumptions!$B$20/(Assumptions!$B$16*1000000000000*Assumptions!$B$17*3600*Assumptions!$B$18)*1000000*Assumptions!$B$21 -> 0.098303561 | F24: =$A24*2*F$21*1000000000*Assumptions!$B$20/(Assumptions!$B$16*1000000000000*Assumptions!$B$17*3600*Assumptions!$B$18)*1000000*Assumptions!$B$21 -> 0.21065049 | G24: =$A24*2*G$21*1000000000*Assumptions!$B$20/(Assumptions!$B$16*1000000000000*Assumptions!$B$17*3600*Assumptions!$B$18)*1000000*Assumptions!$B$21 -> 0.49151781
A25: 3 | B25: =$A25*2*B$21*1000000000*Assumptions!$B$20/(Assumptions!$B$16*1000000000000*Assumptions!$B$17*3600*Assumptions!$B$18)*1000000*Assumptions!$B$21 -> 0.0084260195 | C25: =$A25*2*C$21*1000000000*Assumptions!$B$20/(Assumptions!$B$16*1000000000000*Assumptions!$B$17*3600*Assumptions!$B$18)*1000000*Assumptions!$B$21 -> 0.025278059 | D25: =$A25*2*D$21*1000000000*Assumptions!$B$20/(Assumptions!$B$16*1000000000000*Assumptions!$B$17*3600*Assumptions!$B$18)*1000000*Assumptions!$B$21 -> 0.067408156 | E25: =$A25*2*E$21*1000000000*Assumptions!$B$20/(Assumptions!$B$16*1000000000000*Assumptions!$B$17*3600*Assumptions!$B$18)*1000000*Assumptions!$B$21 -> 0.11796427 | F25: =$A25*2*F$21*1000000000*Assumptions!$B$20/(Assumptions!$B$16*1000000000000*Assumptions!$B$17*3600*Assumptions!$B$18)*1000000*Assumptions!$B$21 -> 0.25278059 | G25: =$A25*2*G$21*1000000000*Assumptions!$B$20/(Assumptions!$B$16*1000000000000*Assumptions!$B$17*3600*Assumptions!$B$18)*1000000*Assumptions!$B$21 -> 0.58982137
A26: 3.84 | B26: =$A26*2*B$21*1000000000*Assumptions!$B$20/(Assumptions!$B$16*1000000000000*Assumptions!$B$17*3600*Assumptions!$B$18)*1000000*Assumptions!$B$21 -> 0.010785305 | C26: =$A26*2*C$21*1000000000*Assumptions!$B$20/(Assumptions!$B$16*1000000000000*Assumptions!$B$17*3600*Assumptions!$B$18)*1000000*Assumptions!$B$21 -> 0.032355915 | D26: =$A26*2*D$21*1000000000*Assumptions!$B$20/(Assumptions!$B$16*1000000000000*Assumptions!$B$17*3600*Assumptions!$B$18)*1000000*Assumptions!$B$21 -> 0.08628244 | E26: =$A26*2*E$21*1000000000*Assumptions!$B$20/(Assumptions!$B$16*1000000000000*Assumptions!$B$17*3600*Assumptions!$B$18)*1000000*Assumptions!$B$21 -> 0.15099427 | F26: =$A26*2*F$21*1000000000*Assumptions!$B$20/(Assumptions!$B$16*1000000000000*Assumptions!$B$17*3600*Assumptions!$B$18)*1000000*Assumptions!$B$21 -> 0.32355915 | G26: =$A26*2*G$21*1000000000*Assumptions!$B$20/(Assumptions!$B$16*1000000000000*Assumptions!$B$17*3600*Assumptions!$B$18)*1000000*Assumptions!$B$21 -> 0.75497135
A27: 5 | B27: =$A27*2*B$21*1000000000*Assumptions!$B$20/(Assumptions!$B$16*1000000000000*Assumptions!$B$17*3600*Assumptions!$B$18)*1000000*Assumptions!$B$21 -> 0.014043366 | C27: =$A27*2*C$21*1000000000*Assumptions!$B$20/(Assumptions!$B$16*1000000000000*Assumptions!$B$17*3600*Assumptions!$B$18)*1000000*Assumptions!$B$21 -> 0.042130098 | D27: =$A27*2*D$21*1000000000*Assumptions!$B$20/(Assumptions!$B$16*1000000000000*Assumptions!$B$17*3600*Assumptions!$B$18)*1000000*Assumptions!$B$21 -> 0.11234693 | E27: =$A27*2*E$21*1000000000*Assumptions!$B$20/(Assumptions!$B$16*1000000000000*Assumptions!$B$17*3600*Assumptions!$B$18)*1000000*Assumptions!$B$21 -> 0.19660712 | F27: =$A27*2*F$21*1000000000*Assumptions!$B$20/(Assumptions!$B$16*1000000000000*Assumptions!$B$17*3600*Assumptions!$B$18)*1000000*Assumptions!$B$21 -> 0.42130098 | G27: =$A27*2*G$21*1000000000*Assumptions!$B$20/(Assumptions!$B$16*1000000000000*Assumptions!$B$17*3600*Assumptions!$B$18)*1000000*Assumptions!$B$21 -> 0.98303561
A29: ="Compare every cell with the net price of $"&TEXT(UnitEcon!$B$16,"0.0000")&" per M tokens." -> Compare every cell with the net price of $0.0404 per M tokens.

Sheet Scale
A1: The Jevons test: how much volume makes the business work?
A2: Volume needed for inference gross profit to cover fixed costs (people, research compute, other), by price.
A4: Fixed costs today
A5: Payroll, current team ($mm / yr) | B5: =Assumptions!$B$35 -> 8.1825
A6: Research compute ($mm / yr) | B6: =Assumptions!$B$39*Assumptions!$B$40*8760/1000000 -> 5.6064
A7: Other opex ($mm / yr) | B7: =Assumptions!$B$37 -> 3
A8: Total fixed costs ($mm / yr) | B8: =SUM(B5:B7) -> 16.7889
A10: Price scenarios (list price, before leakage)
A11: List price ($ / M input tokens) | B11: =Assumptions!$B$6 -> 0.042 | C11: 0.06 | D11: 0.08 | E11: 0.15 | F11: 0.25
A12: Net price after leakage | B12: =B11*(1-UnitEcon!$B$15) -> 0.040404 | C12: =C11*(1-UnitEcon!$B$15) -> 0.05772 | D12: =D11*(1-UnitEcon!$B$15) -> 0.07696 | E12: =E11*(1-UnitEcon!$B$15) -> 0.1443 | F12: =F11*(1-UnitEcon!$B$15) -> 0.2405
A13: Cost to serve ($ / M tokens) | B13: =UnitEcon!$B$12 -> 0.056173464 | C13: =UnitEcon!$B$12 -> 0.056173464 | D13: =UnitEcon!$B$12 -> 0.056173464 | E13: =UnitEcon!$B$12 -> 0.056173464 | F13: =UnitEcon!$B$12 -> 0.056173464
A14: Gross profit ($ / M tokens) | B14: =B12-B13 -> -0.015769464 | C14: =C12-C13 -> 0.0015465363 | D14: =D12-D13 -> 0.020786536 | E14: =E12-E13 -> 0.088126536 | F14: =F12-F13 -> 0.18432654
A15: Gross margin | B15: =IF(B12=0,0,B14/B12) -> -0.39029462 | C15: =IF(C12=0,0,C14/C12) -> 0.026793769 | D15: =IF(D12=0,0,D14/D12) -> 0.27009533 | E15: =IF(E12=0,0,E14/E12) -> 0.61071751 | F15: =IF(F12=0,0,F14/F12) -> 0.7664305
A16: M tokens / yr to cover fixed costs | B16: =IF(B14<=0,"loss per token",$B$8*1000000/B14) -> loss per token | C16: =IF(C14<=0,"loss per token",$B$8*1000000/C14) -> 1.0855807e+10 | D16: =IF(D14<=0,"loss per token",$B$8*1000000/D14) -> 8.0768146e+08 | E16: =IF(E14<=0,"loss per token",$B$8*1000000/E14) -> 1.9050902e+08 | F16: =IF(F14<=0,"loss per token",$B$8*1000000/F14) -> 91082382
A17: Tokens / day needed (trillions) | B17: =IF(B14<=0,"n/a",B16*1000000/365/1000000000000) -> n/a | C17: =IF(C14<=0,"n/a",C16*1000000/365/1000000000000) -> 29.741937 | D17: =IF(D14<=0,"n/a",D16*1000000/365/1000000000000) -> 2.2128259 | E17: =IF(E14<=0,"n/a",E16*1000000/365/1000000000000) -> 0.52194252 | F17: =IF(F14<=0,"n/a",F16*1000000/365/1000000000000) -> 0.24954077
A18: Decisions / day needed (millions) | B18: =IF(B14<=0,"n/a",B16*1000000/365/Assumptions!$B$24/1000000) -> n/a | C18: =IF(C14<=0,"n/a",C16*1000000/365/Assumptions!$B$24/1000000) -> 32570.108 | D18: =IF(D14<=0,"n/a",D16*1000000/365/Assumptions!$B$24/1000000) -> 2423.2443 | E18: =IF(E14<=0,"n/a",E16*1000000/365/Assumptions!$B$24/1000000) -> 571.57421 | F18: =IF(F14<=0,"n/a",F16*1000000/365/Assumptions!$B$24/1000000) -> 273.26969
A19: Serving GPUs needed | B19: =IF(B14<=0,"n/a",B16*1000000/(UnitEcon!$B$10*8760*Assumptions!$B$18)) -> n/a | C19: =IF(C14<=0,"n/a",C16*1000000/(UnitEcon!$B$10*8760*Assumptions!$B$18)) -> 27845.127 | D19: =IF(D14<=0,"n/a",D16*1000000/(UnitEcon!$B$10*8760*Assumptions!$B$18)) -> 2071.7016 | E19: =IF(E14<=0,"n/a",E16*1000000/(UnitEcon!$B$10*8760*Assumptions!$B$18)) -> 488.65532 | F19: =IF(F14<=0,"n/a",F16*1000000/(UnitEcon!$B$10*8760*Assumptions!$B$18)) -> 233.62616
A20: Annual net revenue at break-even ($mm) | B20: =IF(B14<=0,"n/a",B16*B12/1000000) -> n/a | C20: =IF(C14<=0,"n/a",C16*C12/1000000) -> 626.59718 | D20: =IF(D14<=0,"n/a",D16*D12/1000000) -> 62.159165 | E20: =IF(E14<=0,"n/a",E16*E12/1000000) -> 27.490451 | F20: =IF(F14<=0,"n/a",F16*F12/1000000) -> 21.905313
A21: Savings vs. fast LLM (case 1) | B21: =IF(B11=0,0,UnitEcon!$B$35/(Assumptions!$B$24/1000000*B11)) -> 67.899947 | C21: =IF(C11=0,0,UnitEcon!$B$35/(Assumptions!$B$24/1000000*C11)) -> 47.529963 | D21: =IF(D11=0,0,UnitEcon!$B$35/(Assumptions!$B$24/1000000*D11)) -> 35.647472 | E21: =IF(E11=0,0,UnitEcon!$B$35/(Assumptions!$B$24/1000000*E11)) -> 19.011985 | F21: =IF(F11=0,0,UnitEcon!$B$35/(Assumptions!$B$24/1000000*F11)) -> 11.407191
A22: Savings vs. reasoning LLM (case 2) | B22: =IF(B11=0,0,UnitEcon!$B$38/(Assumptions!$B$24/1000000*B11)) -> 76.925751 | C22: =IF(C11=0,0,UnitEcon!$B$38/(Assumptions!$B$24/1000000*C11)) -> 53.848026 | D22: =IF(D11=0,0,UnitEcon!$B$38/(Assumptions!$B$24/1000000*D11)) -> 40.386019 | E22: =IF(E11=0,0,UnitEcon!$B$38/(Assumptions!$B$24/1000000*E11)) -> 21.53921 | F22: =IF(F11=0,0,UnitEcon!$B$38/(Assumptions!$B$24/1000000*F11)) -> 12.923526
A24: Read across: raising the price cuts the volume needed to break even sharply, while savings vs. LLMs stay large.

Sheet Runway
A1: 24-month cash and runway (illustrative, no new funding)
A2: Monthly build. Headcount follows the Hiring tab; volume grows and cost per token falls per Assumptions.
A4: Month | B4: 1 | C4: 2 | D4: 3 | E4: 4 | F4: 5 | G4: 6 | H4: 7 | I4: 8 | J4: 9 | K4: 10 | L4: 11 | M4: 12 | N4: 13 | O4: 14 | P4: 15 | Q4: 16 | R4: 17 | S4: 18 | T4: 19 | U4: 20 | V4: 21 | W4: 22 | X4: 23 | Y4: 24
A5: Headcount | B5: =Hiring!$D$32+SUMPRODUCT((Hiring!$E$37:$E$66>=1)*(Hiring!$E$37:$E$66<=B$4)*Hiring!$D$37:$D$66) -> 25 | C5: =Hiring!$D$32+SUMPRODUCT((Hiring!$E$37:$E$66>=1)*(Hiring!$E$37:$E$66<=C$4)*Hiring!$D$37:$D$66) -> 26 | D5: =Hiring!$D$32+SUMPRODUCT((Hiring!$E$37:$E$66>=1)*(Hiring!$E$37:$E$66<=D$4)*Hiring!$D$37:$D$66) -> 26 | E5: =Hiring!$D$32+SUMPRODUCT((Hiring!$E$37:$E$66>=1)*(Hiring!$E$37:$E$66<=E$4)*Hiring!$D$37:$D$66) -> 26 | F5: =Hiring!$D$32+SUMPRODUCT((Hiring!$E$37:$E$66>=1)*(Hiring!$E$37:$E$66<=F$4)*Hiring!$D$37:$D$66) -> 26 | G5: =Hiring!$D$32+SUMPRODUCT((Hiring!$E$37:$E$66>=1)*(Hiring!$E$37:$E$66<=G$4)*Hiring!$D$37:$D$66) -> 26 | H5: =Hiring!$D$32+SUMPRODUCT((Hiring!$E$37:$E$66>=1)*(Hiring!$E$37:$E$66<=H$4)*Hiring!$D$37:$D$66) -> 26 | I5: =Hiring!$D$32+SUMPRODUCT((Hiring!$E$37:$E$66>=1)*(Hiring!$E$37:$E$66<=I$4)*Hiring!$D$37:$D$66) -> 26 | ... Y5: =Hiring!$D$32+SUMPRODUCT((Hiring!$E$37:$E$66>=1)*(Hiring!$E$37:$E$66<=Y$4)*Hiring!$D$37:$D$66) -> 26
A6: Payroll ($mm) | B6: =(Hiring!$H$32+SUMPRODUCT((Hiring!$E$37:$E$66>=1)*(Hiring!$E$37:$E$66<=B$4)*Hiring!$D$37:$D$66*Hiring!$H$37:$H$66))/1000/12 -> 0.681875 | C6: =(Hiring!$H$32+SUMPRODUCT((Hiring!$E$37:$E$66>=1)*(Hiring!$E$37:$E$66<=C$4)*Hiring!$D$37:$D$66*Hiring!$H$37:$H$66))/1000/12 -> 0.70166667 | D6: =(Hiring!$H$32+SUMPRODUCT((Hiring!$E$37:$E$66>=1)*(Hiring!$E$37:$E$66<=D$4)*Hiring!$D$37:$D$66*Hiring!$H$37:$H$66))/1000/12 -> 0.70166667 | E6: =(Hiring!$H$32+SUMPRODUCT((Hiring!$E$37:$E$66>=1)*(Hiring!$E$37:$E$66<=E$4)*Hiring!$D$37:$D$66*Hiring!$H$37:$H$66))/1000/12 -> 0.70166667 | F6: =(Hiring!$H$32+SUMPRODUCT((Hiring!$E$37:$E$66>=1)*(Hiring!$E$37:$E$66<=F$4)*Hiring!$D$37:$D$66*Hiring!$H$37:$H$66))/1000/12 -> 0.70166667 | G6: =(Hiring!$H$32+SUMPRODUCT((Hiring!$E$37:$E$66>=1)*(Hiring!$E$37:$E$66<=G$4)*Hiring!$D$37:$D$66*Hiring!$H$37:$H$66))/1000/12 -> 0.70166667 | H6: =(Hiring!$H$32+SUMPRODUCT((Hiring!$E$37:$E$66>=1)*(Hiring!$E$37:$E$66<=H$4)*Hiring!$D$37:$D$66*Hiring!$H$37:$H$66))/1000/12 -> 0.70166667 | I6: =(Hiring!$H$32+SUMPRODUCT((Hiring!$E$37:$E$66>=1)*(Hiring!$E$37:$E$66<=I$4)*Hiring!$D$37:$D$66*Hiring!$H$37:$H$66))/1000/12 -> 0.70166667 | ... Y6: =(Hiring!$H$32+SUMPRODUCT((Hiring!$E$37:$E$66>=1)*(Hiring!$E$37:$E$66<=Y$4)*Hiring!$D$37:$D$66*Hiring!$H$37:$H$66))/1000/12 -> 0.70166667
A7: Research compute ($mm) | B7: =Assumptions!$B$39*Assumptions!$B$40*730/1000000 -> 0.4672 | C7: =Assumptions!$B$39*Assumptions!$B$40*730/1000000 -> 0.4672 | D7: =Assumptions!$B$39*Assumptions!$B$40*730/1000000 -> 0.4672 | E7: =Assumptions!$B$39*Assumptions!$B$40*730/1000000 -> 0.4672 | F7: =Assumptions!$B$39*Assumptions!$B$40*730/1000000 -> 0.4672 | G7: =Assumptions!$B$39*Assumptions!$B$40*730/1000000 -> 0.4672 | H7: =Assumptions!$B$39*Assumptions!$B$40*730/1000000 -> 0.4672 | I7: =Assumptions!$B$39*Assumptions!$B$40*730/1000000 -> 0.4672 | ... Y7: =Assumptions!$B$39*Assumptions!$B$40*730/1000000 -> 0.4672
A8: Other opex ($mm) | B8: =Assumptions!$B$37/12 -> 0.25 | C8: =Assumptions!$B$37/12 -> 0.25 | D8: =Assumptions!$B$37/12 -> 0.25 | E8: =Assumptions!$B$37/12 -> 0.25 | F8: =Assumptions!$B$37/12 -> 0.25 | G8: =Assumptions!$B$37/12 -> 0.25 | H8: =Assumptions!$B$37/12 -> 0.25 | I8: =Assumptions!$B$37/12 -> 0.25 | ... Y8: =Assumptions!$B$37/12 -> 0.25
A9: Free credits, at compute cost ($mm) | B9: =IF(Assumptions!$B$6=0,0,Assumptions!$B$45*Assumptions!$B$10*Assumptions!$B$46*B13/Assumptions!$B$6/1000000) -> 0.0060185854 | C9: =IF(Assumptions!$B$6=0,0,Assumptions!$B$45*Assumptions!$B$10*Assumptions!$B$46*C13/Assumptions!$B$6/1000000) -> 0.0058380278 | D9: =IF(Assumptions!$B$6=0,0,Assumptions!$B$45*Assumptions!$B$10*Assumptions!$B$46*D13/Assumptions!$B$6/1000000) -> 0.005662887 | E9: =IF(Assumptions!$B$6=0,0,Assumptions!$B$45*Assumptions!$B$10*Assumptions!$B$46*E13/Assumptions!$B$6/1000000) -> 0.0054930004 | F9: =IF(Assumptions!$B$6=0,0,Assumptions!$B$45*Assumptions!$B$10*Assumptions!$B$46*F13/Assumptions!$B$6/1000000) -> 0.0053282104 | G9: =IF(Assumptions!$B$6=0,0,Assumptions!$B$45*Assumptions!$B$10*Assumptions!$B$46*G13/Assumptions!$B$6/1000000) -> 0.0051683641 | H9: =IF(Assumptions!$B$6=0,0,Assumptions!$B$45*Assumptions!$B$10*Assumptions!$B$46*H13/Assumptions!$B$6/1000000) -> 0.0050133131 | I9: =IF(Assumptions!$B$6=0,0,Assumptions!$B$45*Assumptions!$B$10*Assumptions!$B$46*I13/Assumptions!$B$6/1000000) -> 0.0048629137 | ... Y9: =IF(Assumptions!$B$6=0,0,Assumptions!$B$45*Assumptions!$B$10*Assumptions!$B$46*Y13/Assumptions!$B$6/1000000) -> 0.0029870625
A10: Billed tokens / day (B) | B10: =Assumptions!$B$48*(1+Assumptions!$B$51)^(B$4-1) -> 90 | C10: =Assumptions!$B$48*(1+Assumptions!$B$51)^(C$4-1) -> 103.5 | D10: =Assumptions!$B$48*(1+Assumptions!$B$51)^(D$4-1) -> 119.025 | E10: =Assumptions!$B$48*(1+Assumptions!$B$51)^(E$4-1) -> 136.87875 | F10: =Assumptions!$B$48*(1+Assumptions!$B$51)^(F$4-1) -> 157.41056 | G10: =Assumptions!$B$48*(1+Assumptions!$B$51)^(G$4-1) -> 181.02215 | H10: =Assumptions!$B$48*(1+Assumptions!$B$51)^(H$4-1) -> 208.17547 | I10: =Assumptions!$B$48*(1+Assumptions!$B$51)^(I$4-1) -> 239.40179 | ... Y10: =Assumptions!$B$48*(1+Assumptions!$B$51)^(Y$4-1) -> 2240.2312
A11: Decisions / day (mm) | B11: =B10*1000000000/Assumptions!$B$24/1000000 -> 98.558131 | C11: =C10*1000000000/Assumptions!$B$24/1000000 -> 113.34185 | D11: =D10*1000000000/Assumptions!$B$24/1000000 -> 130.34313 | E11: =E10*1000000000/Assumptions!$B$24/1000000 -> 149.8946 | F11: =F10*1000000000/Assumptions!$B$24/1000000 -> 172.37879 | G11: =G10*1000000000/Assumptions!$B$24/1000000 -> 198.23561 | H11: =H10*1000000000/Assumptions!$B$24/1000000 -> 227.97095 | I11: =I10*1000000000/Assumptions!$B$24/1000000 -> 262.16659 | ... Y11: =Y10*1000000000/Assumptions!$B$24/1000000 -> 2453.2555
A12: Tokens served (M tokens / month) | B12: =B10*1000000000*30.4/1000000 -> 2736000 | C12: =C10*1000000000*30.4/1000000 -> 3146400 | D12: =D10*1000000000*30.4/1000000 -> 3618360 | E12: =E10*1000000000*30.4/1000000 -> 4161114 | F12: =F10*1000000000*30.4/1000000 -> 4785281.1 | G12: =G10*1000000000*30.4/1000000 -> 5503073.3 | H12: =H10*1000000000*30.4/1000000 -> 6328534.3 | I12: =I10*1000000000*30.4/1000000 -> 7277814.4 | ... Y12: =Y10*1000000000*30.4/1000000 -> 68103028
A13: Cost to serve ($ / M tokens) | B13: =UnitEcon!$B$12*(1-Assumptions!$B$52)^(B$4-1) -> 0.056173464 | C13: =UnitEcon!$B$12*(1-Assumptions!$B$52)^(C$4-1) -> 0.05448826 | D13: =UnitEcon!$B$12*(1-Assumptions!$B$52)^(D$4-1) -> 0.052853612 | E13: =UnitEcon!$B$12*(1-Assumptions!$B$52)^(E$4-1) -> 0.051268004 | F13: =UnitEcon!$B$12*(1-Assumptions!$B$52)^(F$4-1) -> 0.049729963 | G13: =UnitEcon!$B$12*(1-Assumptions!$B$52)^(G$4-1) -> 0.048238065 | H13: =UnitEcon!$B$12*(1-Assumptions!$B$52)^(H$4-1) -> 0.046790923 | I13: =UnitEcon!$B$12*(1-Assumptions!$B$52)^(I$4-1) -> 0.045387195 | ... Y13: =UnitEcon!$B$12*(1-Assumptions!$B$52)^(Y$4-1) -> 0.02787925
A14: Gross revenue ($mm) | B14: =B12*Assumptions!$B$6/1000000 -> 0.114912 | C14: =C12*Assumptions!$B$6/1000000 -> 0.1321488 | D14: =D12*Assumptions!$B$6/1000000 -> 0.15197112 | E14: =E12*Assumptions!$B$6/1000000 -> 0.17476679 | F14: =F12*Assumptions!$B$6/1000000 -> 0.20098181 | G14: =G12*Assumptions!$B$6/1000000 -> 0.23112908 | H14: =H12*Assumptions!$B$6/1000000 -> 0.26579844 | I14: =I12*Assumptions!$B$6/1000000 -> 0.3056682 | ... Y14: =Y12*Assumptions!$B$6/1000000 -> 2.8603272
A15: Gateway and payment fees ($mm) | B15: =B14*UnitEcon!$B$15 -> 0.004366656 | C15: =C14*UnitEcon!$B$15 -> 0.0050216544 | D15: =D14*UnitEcon!$B$15 -> 0.0057749026 | E15: =E14*UnitEcon!$B$15 -> 0.0066411379 | F15: =F14*UnitEcon!$B$15 -> 0.0076373086 | G15: =G14*UnitEcon!$B$15 -> 0.0087829049 | H15: =H14*UnitEcon!$B$15 -> 0.010100341 | I15: =I14*UnitEcon!$B$15 -> 0.011615392 | ... Y15: =Y14*UnitEcon!$B$15 -> 0.10869243
A16: Net revenue ($mm) | B16: =B14-B15 -> 0.11054534 | C16: =C14-C15 -> 0.12712715 | D16: =D14-D15 -> 0.14619622 | E16: =E14-E15 -> 0.16812565 | F16: =F14-F15 -> 0.1933445 | G16: =G14-G15 -> 0.22234617 | H16: =H14-H15 -> 0.2556981 | I16: =I14-I15 -> 0.29405281 | ... Y16: =Y14-Y15 -> 2.7516347
A17: Cost of serving ($mm) | B17: =B12*B13/1000000 -> 0.1536906 | C17: =C12*C13/1000000 -> 0.17144186 | D17: =D12*D13/1000000 -> 0.1912434 | E17: =E12*E13/1000000 -> 0.21333201 | F17: =F12*F13/1000000 -> 0.23797185 | G17: =G12*G13/1000000 -> 0.2654576 | H17: =H12*H13/1000000 -> 0.29611796 | I17: =I12*I13/1000000 -> 0.33031958 | ... Y17: =Y12*Y13/1000000 -> 1.8986614
A18: Gross profit ($mm) | B18: =B16-B17 -> -0.043145253 | C18: =C16-C17 -> -0.044314715 | D18: =D16-D17 -> -0.045047178 | E18: =E16-E17 -> -0.045206357 | F18: =F16-F17 -> -0.044627357 | G18: =G16-G17 -> -0.043111431 | H18: =H16-H17 -> -0.040419859 | I18: =I16-I17 -> -0.036266768 | ... Y18: =Y16-Y17 -> 0.85297338
A19: Gross margin | B19: =IF(B16=0,0,B18/B16) -> -0.39029462 | C19: =IF(C16=0,0,C18/C16) -> -0.34858578 | D19: =IF(D16=0,0,D18/D16) -> -0.3081282 | E19: =IF(E16=0,0,E18/E16) -> -0.26888436 | F19: =IF(F16=0,0,F18/F16) -> -0.23081783 | G19: =IF(G16=0,0,G18/G16) -> -0.19389329 | H19: =IF(H16=0,0,H18/H16) -> -0.15807649 | I19: =IF(I16=0,0,I18/I16) -> -0.1233342 | ... Y19: =IF(Y16=0,0,Y18/Y16) -> 0.30998786
A20: Net burn ($mm) | B20: =B6+B7+B8+B9-B18 -> 1.4482388 | C20: =C6+C7+C8+C9-C18 -> 1.4690194 | D20: =D6+D7+D8+D9-D18 -> 1.4695767 | E20: =E6+E7+E8+E9-E18 -> 1.469566 | F20: =F6+F7+F8+F9-F18 -> 1.4688222 | G20: =G6+G7+G8+G9-G18 -> 1.4671465 | H20: =H6+H7+H8+H9-H18 -> 1.4642998 | I20: =I6+I7+I8+I9-I18 -> 1.4599963 | ... Y20: =Y6+Y7+Y8+Y9-Y18 -> 0.56888035
A21: Cumulative burn ($mm) | B21: =B20 -> 1.4482388 | C21: =B21+C20 -> 2.9172582 | D21: =C21+D20 -> 4.386835 | E21: =D21+E20 -> 5.856401 | F21: =E21+F20 -> 7.3252232 | G21: =F21+G20 -> 8.7923697 | H21: =G21+H20 -> 10.25667 | I21: =H21+I20 -> 11.716666 | J21: =I21+J20 -> 13.17056 | ... Y21: =X21+Y20 -> 30.784782
A22: Cash, end of month, base case ($mm) | B22: =Assumptions!$B$32-B21 -> 28.551761 | C22: =Assumptions!$B$32-C21 -> 27.082742 | D22: =Assumptions!$B$32-D21 -> 25.613165 | E22: =Assumptions!$B$32-E21 -> 24.143599 | F22: =Assumptions!$B$32-F21 -> 22.674777 | G22: =Assumptions!$B$32-G21 -> 21.20763 | H22: =Assumptions!$B$32-H21 -> 19.74333 | I22: =Assumptions!$B$32-I21 -> 18.283334 | ... Y22: =Assumptions!$B$32-Y21 -> -0.78478215
A23: Gross profit positive? (1 = yes) | B23: =IF(B18>0,1,0) -> 0 | C23: =IF(C18>0,1,0) -> 0 | D23: =IF(D18>0,1,0) -> 0 | E23: =IF(E18>0,1,0) -> 0 | F23: =IF(F18>0,1,0) -> 0 | G23: =IF(G18>0,1,0) -> 0 | H23: =IF(H18>0,1,0) -> 0 | I23: =IF(I18>0,1,0) -> 0 | ... Y23: =IF(Y18>0,1,0) -> 1
A24: Funded? low cash case | B24: =IF(Assumptions!$B$31-B21>0,1,0) -> 1 | C24: =IF(AND(B24=1,Assumptions!$B$31-C21>0),1,0) -> 1 | D24: =IF(AND(C24=1,Assumptions!$B$31-D21>0),1,0) -> 1 | E24: =IF(AND(D24=1,Assumptions!$B$31-E21>0),1,0) -> 1 | F24: =IF(AND(E24=1,Assumptions!$B$31-F21>0),1,0) -> 1 | G24: =IF(AND(F24=1,Assumptions!$B$31-G21>0),1,0) -> 1 | H24: =IF(AND(G24=1,Assumptions!$B$31-H21>0),1,0) -> 1 | I24: =IF(AND(H24=1,Assumptions!$B$31-I21>0),1,0) -> 1 | J24: =IF(AND(I24=1,Assumptions!$B$31-J21>0),1,0) -> 1 | ... Y24: =IF(AND(X24=1,Assumptions!$B$31-Y21>0),1,0) -> 0
A25: Funded? base cash case | B25: =IF(Assumptions!$B$32-B21>0,1,0) -> 1 | C25: =IF(AND(B25=1,Assumptions!$B$32-C21>0),1,0) -> 1 | D25: =IF(AND(C25=1,Assumptions!$B$32-D21>0),1,0) -> 1 | E25: =IF(AND(D25=1,Assumptions!$B$32-E21>0),1,0) -> 1 | F25: =IF(AND(E25=1,Assumptions!$B$32-F21>0),1,0) -> 1 | G25: =IF(AND(F25=1,Assumptions!$B$32-G21>0),1,0) -> 1 | H25: =IF(AND(G25=1,Assumptions!$B$32-H21>0),1,0) -> 1 | I25: =IF(AND(H25=1,Assumptions!$B$32-I21>0),1,0) -> 1 | J25: =IF(AND(I25=1,Assumptions!$B$32-J21>0),1,0) -> 1 | ... Y25: =IF(AND(X25=1,Assumptions!$B$32-Y21>0),1,0) -> 0
A26: Funded? high cash case | B26: =IF(Assumptions!$B$33-B21>0,1,0) -> 1 | C26: =IF(AND(B26=1,Assumptions!$B$33-C21>0),1,0) -> 1 | D26: =IF(AND(C26=1,Assumptions!$B$33-D21>0),1,0) -> 1 | E26: =IF(AND(D26=1,Assumptions!$B$33-E21>0),1,0) -> 1 | F26: =IF(AND(E26=1,Assumptions!$B$33-F21>0),1,0) -> 1 | G26: =IF(AND(F26=1,Assumptions!$B$33-G21>0),1,0) -> 1 | H26: =IF(AND(G26=1,Assumptions!$B$33-H21>0),1,0) -> 1 | I26: =IF(AND(H26=1,Assumptions!$B$33-I21>0),1,0) -> 1 | J26: =IF(AND(I26=1,Assumptions!$B$33-J21>0),1,0) -> 1 | ... Y26: =IF(AND(X26=1,Assumptions!$B$33-Y21>0),1,0) -> 1
A27: Payroll, current team only ($mm) | B27: =Hiring!$H$32/1000/12 -> 0.681875 | C27: =Hiring!$H$32/1000/12 -> 0.681875 | D27: =Hiring!$H$32/1000/12 -> 0.681875 | E27: =Hiring!$H$32/1000/12 -> 0.681875 | F27: =Hiring!$H$32/1000/12 -> 0.681875 | G27: =Hiring!$H$32/1000/12 -> 0.681875 | H27: =Hiring!$H$32/1000/12 -> 0.681875 | I27: =Hiring!$H$32/1000/12 -> 0.681875 | ... Y27: =Hiring!$H$32/1000/12 -> 0.681875
A28: Net burn without planned hires ($mm) | B28: =B20-B6+B27 -> 1.4482388 | C28: =C20-C6+C27 -> 1.4492277 | D28: =D20-D6+D27 -> 1.4497851 | E28: =E20-E6+E27 -> 1.4497744 | F28: =F20-F6+F27 -> 1.4490306 | G28: =G20-G6+G27 -> 1.4473548 | H28: =H20-H6+H27 -> 1.4445082 | I28: =I20-I6+I27 -> 1.4402047 | ... Y28: =Y20-Y6+Y27 -> 0.54908869
A29: Cumulative burn without planned hires ($mm) | B29: =B28 -> 1.4482388 | C29: =B29+C28 -> 2.8974666 | D29: =C29+D28 -> 4.3472516 | E29: =D29+E28 -> 5.797026 | F29: =E29+F28 -> 7.2460566 | G29: =F29+G28 -> 8.6934114 | H29: =G29+H28 -> 10.13792 | I29: =H29+I28 -> 11.578124 | J29: =I29+J28 -> 13.012227 | ... Y29: =X29+Y28 -> 30.329574
A30: Funded? base cash, no planned hires | B30: =IF(Assumptions!$B$32-B29>0,1,0) -> 1 | C30: =IF(AND(B30=1,Assumptions!$B$32-C29>0),1,0) -> 1 | D30: =IF(AND(C30=1,Assumptions!$B$32-D29>0),1,0) -> 1 | E30: =IF(AND(D30=1,Assumptions!$B$32-E29>0),1,0) -> 1 | F30: =IF(AND(E30=1,Assumptions!$B$32-F29>0),1,0) -> 1 | G30: =IF(AND(F30=1,Assumptions!$B$32-G29>0),1,0) -> 1 | H30: =IF(AND(G30=1,Assumptions!$B$32-H29>0),1,0) -> 1 | I30: =IF(AND(H30=1,Assumptions!$B$32-I29>0),1,0) -> 1 | J30: =IF(AND(I30=1,Assumptions!$B$32-J29>0),1,0) -> 1 | ... Y30: =IF(AND(X30=1,Assumptions!$B$32-Y29>0),1,0) -> 0
A32: Summary (24 = funded for at least the full 24 months)
A33: Runway, low cash case (months) | B33: =SUM(B24:Y24) -> 13
A34: Runway, base cash case (months) | B34: =SUM(B25:Y25) -> 22
A35: Runway, high cash case (months) | B35: =SUM(B26:Y26) -> 24
A36: Runway, base cash, without planned hires (months) | B36: =SUM(B30:Y30) -> 23
A37: Runway used up by planned hires (months) | B37: =B36-B34 -> 1
A38: First month gross profit turns positive | B38: =IFERROR(MATCH(1,B23:Y23,0),"not within 24 months") -> 12
A39: Cumulative gross profit, 24 months ($mm) | B39: =SUM(B18:Y18) -> 3.352264

Sheet LiveTest
A1: Live test: measure real tokens, cost, latency and agreement
A2: Section 1 is already measured. Section 2 fills in when you run jev_live_test.py with your own API keys and paste the CSV rows.
A4: Live results below are from the Sep 29 2026 run (Claude Haiku 4.5 and GPT-5.6 Terra via OpenRouter). To re-run, see the header of jev_live_test.py. Keys stay in your terminal as environment variables; nothing is stored in this workbook.
A5: 1. Sample workloads, counted offline
A6: Workload | B6: Questions | C6: State tokens | D6: Question tokens | E6: Total input tokens | F6: What it represents
A7: GL transaction coding | B7: 2 | C7: 357 | D7: 349 | E7: 715 | F7: Assign a bank transaction to a general-ledger account, with recent coding history for the same vendor as context.
A8: Vendor invoice approval check | B8: 3 | C8: 253 | D8: 184 | E8: 447 | F8: Decide whether an incoming invoice can be auto-approved against the purchase order and contract terms.
A9: Support ticket routing | B9: 3 | C9: 173 | D9: 185 | E9: 369 | F9: Route an inbound customer email to the right queue and set priority.
A10: Expense report policy check | B10: 2 | C10: 273 | D10: 93 | E10: 375 | F10: Check an employee expense report against the travel and expense policy.
A11: Contract clause risk scoring | B11: 3 | C11: 461 | D11: 154 | E11: 625 | F11: Score the risk of a customer contract's liability and indemnity clauses for a sales-ops review queue.
A12: Inbound lead qualification | B12: 2 | C12: 111 | D12: 63 | E12: 184 | F12: Score a self-serve signup for sales follow-up.
A13: Average | E13: =AVERAGE(E7:E12) -> 452.5
A14: Counted with OpenAI's o200k tokenizer as a proxy; Jev's tokenizer is not public, so expect +/- 20%. Total = the full request body (state + questions + model name).
A16: 2. Live results: paste jev_live_results.csv here (row 18 onward, one row per workload per LLM run)
